Workbook

Sheet COVER SHEET
A1: This workbook describes all the demand side input data for the Python model.
A2: In an effort to create this model with as much open-source data as possible, numerous simplifications and assumption had to be taken. These are tracked as far as possible, but a few sub-models that feed into this input workbook could not directly be included herein.
A5: Sheet name | B5: Discription
A6: Sankey | B6: Material flow Sankey across life cycle stage
A7: Final Exhibits | B7: Demand side summary figures as shown in Planet Positive Chemicals
A8: Job + CO2 Analysis | B8: Jobs creation & CO2 emissions of demand side measures
A9: Side calc. | B9: Useful side calculation
A10: Yearly Summary | B10: Yearly demand by chemical and pyrolysis oil availability across scenarios
A11: Yearly XX | B11: Yearly mass flow breakdown and demand evolution by chemical
A12: Scope 3 Summary | B12: Scope 3 emissions factors by chemical/year
A13: Scope 3 Yearly | B13: Scope 3 emissions factors by end of life treatment
A14: Per Capita Plastic | B14: Geographical per capita plastics demand analysis & comparison
A15: Yearly Demand XX | B15: Demand baseline assumptions per chemical
A16: Demand Breakdown | B16: Demand breakdown by sub chemicals & applications
... A23: Sankey XX | B23: Sankey of demand breakdown by chemical

Sheet Sankey
A1: Sankey - For Carbon only !!
A2: For 2020
B3: Box #1 Feedstock | F3: Box #2: Chemical Production | J3: Box #3: Product Manufacturing | N3: Box #4: Use Phase | R3: Box #5: End-of-use
B4: Mt in 2050 | C4: % | F4: Mt in 2050 | G4: % | J4: Mt in 2050 | K4: % | N4: Mt in 2050 | O4: % | R4: Mt in 2050 | S4: %
A5: Fossil | B5: =C5*$B$10 -> 486.18905 | C5: 0.995 | E5: Depolymerization | F5: =R6 -> 0 | G5: =F5/$F$28 -> 0 | I5: Mechanical recycling | J5: ='Job + CO2 Analysis'!D22 -> 30.3155 | K5: =J5/$F$41 -> 0.054564391 | M5: Resuse | N5: ='Final Exhibits'!H5 -> 0 | O5: =N5/$N$7 -> 0 | Q5: Mechanical recycling | R5: ='Job + CO2 Analysis'!D22 -> 30.3155 | S5: =R5/SUM($R$35) -> 0.058549885
A6: Biomass | B6: =C6*$B$10 -> 2.443161 | C6: 0.005 | E6: Chemical production | F6: =SUM('Final Exhibits'!B4:B10)-19 -> 488.63221 | G6: =F6/$F$7 -> 1 | I6: Product Manufacturing | J6: =F7 -> 488.63221 | K6: =J6/$J$7 -> 0.94158275 | M6: Use | N6: =J7 -> 518.94771 | O6: =N6/$N$7 -> 1 | Q6: Depolymerization | R6: ='Job + CO2 Analysis'!BN3 -> 0 | S6: =R6/SUM($R$35) -> 0
A7: Point Source | B7: =C7*$B$31 -> 0 | C7: 0 | E7: Total production: | F7: =SUM(F5:F6) -> 488.63221 | G7: =F7/$F$7 -> 1 | I7: Total manufacturing: | J7: =SUM(J5:J6) -> 518.94771 | K7: =J7/$J$7 -> 1 | M7: Total use: | N7: =SUM(N5:N6) -> 518.94771 | O7: =N7/$N$7 -> 1 | Q7: Waste feedstock | R7: =B9 -> 0 | S7: =R7/SUM($R$35) -> 0
A8: DAC | B8: =C8*$B$31 -> 0 | C8: 0 | Q8: Incineration without CCS | R8: ='Job + CO2 Analysis'!D25+0.27*N6*AA8/SUM(AA8:AA12) -> 91.891809 | S8: =R8/SUM($R$35) -> 0.17747537 | AA8: ='Scope 3 Yearly'!AH11/SUM('Scope 3 Yearly'!$AH$11:$AH$16) -> 0.32
A9: Waste | B9: =C9*$B$31 -> 0 | C9: 0 | Q9: Open burning | R9: ='Job + CO2 Analysis'!D28 -> 79.404851 | S9: =R9/SUM($R$35) -> 0.15335867 | AA9: ='Scope 3 Yearly'!AH14/SUM('Scope 3 Yearly'!$AH$11:$AH$16) -> 0.16
A10: Total | B10: =F6 -> 488.63221 | Q10: Incineration with CCS | R10: =0 -> 0 | S10: =R10/SUM($R$35) -> 0 | AA10: =0 -> 0
Q11: Landfill | R11: ='Job + CO2 Analysis'!D26 -> 108.81406 | S11: =R11/SUM($R$35) -> 0.21015818 | AA11: ='Scope 3 Yearly'!AH12/SUM('Scope 3 Yearly'!$AH$11:$AH$16) -> 0.42
A12: Note Point source /waste can come from within or other industries | Q12: Leakage | R12: ='Job + CO2 Analysis'!D27+'Job + CO2 Analysis'!D29+'Job + CO2 Analysis'!D30 -> 58.818408 | S12: =R12/SUM($R$35) -> 0.11359902 | AA12: =SUM('Scope 3 Yearly'!AH13,'Scope 3 Yearly'!AH15,'Scope 3 Yearly'!AH16)/SUM('Scope 3 Yearly'!$AH$11:$AH$16) -> 0.1
A13: No quanitfication has been made but it must be shown visually | Q13: Accumulate in the economy | R13: =N6-SUM(R5:R12) -> 149.70308 | S13: =R13/SUM($R$35) -> 0.28912926 | AA13: =R13/N7 -> 0.28847431 | AB13: =1-AA13 -> 0.71152569
A14: Number in yellow estimated from the demand model (feedstock in t of C for Ar&Ol excluding hydrogen) | Q14: Total end-of-use | R14: =SUM(R5:R13) -> 518.94771
A18: Not shown
E19: Elimination | F19: 0 | G19: =F19/$F$41 -> 0 | I19: Elimination | J19: =F19 -> 0 | K19: =J19/$J$41 -> 0 | M19: Elimination | N19: =J19 -> 0 | O19: =N19/$N$41 -> 0
E20: Substitution | F20: 0 | G20: =F20/$F$41 -> 0 | I20: Substitution | J20: =F20 -> 0 | K20: =J20/$J$41 -> 0 | M20: Substitution | N20: =J20 -> 0 | O20: =N20/$N$41 -> 0
E21: Total utility: | F21: =SUM(F7:F20) -> 488.63221 | G21: =F21/$F$21 -> 1 | I21: Total utility: | J21: =SUM(J7,J19,J20) -> 518.94771 | K21: =J21/$J$21 -> 1 | M21: Total utility: | N21: =SUM(N7,N19,N20) -> 518.94771 | O21: =N21/$N$21 -> 1
A23: For Most Economic / Low circularity - 2050
B24: Box #1 Feedstock | F24: Box #2: Chemical Production | J24: Box #3: Product Manufacturing | N24: Box #4: Use Phase | R24: Box #5: End-of-use
B25: Mt in 2050 | C25: % | F25: Mt in 2050 | G25: % | J25: Mt in 2050 | K25: % | N25: Mt in 2050 | O25: % | R25: Mt in 2050 | S25: %
A26: Fossil | B26: =C26*$B$31 -> 288.42852 | C26: 0.74100509 | E26: Depolymerization | F26: =R27 -> 6.3205161 | G26: =F26/$F$28 -> 0.015978649 | I26: Mechanical recycling | J26: =R26 -> 122.21205 | K26: =J26/$J$28 -> 0.23603442 | M26: Resuse | N26: ='Final Exhibits'!H25 -> 69.008255 | O26: =N26/$N$28 -> 0.1176049 | Q26: Mechanical recycling | R26: ='Job + CO2 Analysis'!BN22 -> 122.21205 | S26: =R26/SUM($R$35) -> 0.23603442
A27: Biomass | B27: =C27*$B$31 -> 59.925313 | C27: 0.15395482 | E27: Chemical production | F27: =SUM('Final Exhibits'!K16:K22)-'Final Exhibits'!E10-'Final Exhibits'!B10+'Yearly Summary'!D37 -> 389.23959 | G27: =F27/$F$28 -> 0.98402135 | I27: Product Manufacturing | J27: =F28 -> 395.56011 | K27: =J27/$J$28 -> 0.76396558 | M27: Use | N27: =J28 -> 517.77216 | O27: =N27/$N$28 -> 0.8823951 | Q27: Depolymerization | R27: ='Job + CO2 Analysis'!BN23 -> 6.3205161 | S27: =R27/SUM($R$35) -> 0.012207138
A28: Point Source | B28: =C28*$B$31 -> 29.571366 | C28: 0.075972144 | E28: Total production: | F28: =SUM(F26:F27) -> 395.56011 | G28: =F28/$F$28 -> 1 | I28: Total manufacturing: | J28: =SUM(J26:J27) -> 517.77216 | K28: =J28/$J$28 -> 1 | M28: Total use: | N28: =SUM(N26:N27) -> 586.78042 | O28: =N28/$N$28 -> 1 | Q28: Waste feedstock | R28: =B30 -> 11.314394 | S28: =R28/SUM($R$35) -> 0.021852071
A29: DAC | B29: =C29*$B$31 -> 0 | C29: 0 | Q29: Incineration without CCS | R29: ='Scope 3 Yearly'!BN19 -> 0.7767834 | S29: =R29/SUM($R$35) -> 0.0015002417
A30: Waste | B30: =C30*$B$31 -> 11.314394 | C30: 0.029067942 | Q30: Open burning | R30: ='Scope 3 Yearly'!BN14 -> 39.251562 | S30: =R30/SUM($R$35) -> 0.075808559
A31: Total | B31: =F27 -> 389.23959 | Q31: Incineration with CCS | R31: ='Scope 3 Yearly'!BN20-R28*'Scope 3 Yearly'!BN20/('Scope 3 Yearly'!BN20+'Scope 3 Yearly'!BN12) -> 72.861225 | S31: =R31/SUM($R$35) -> 0.14072063
F32: =B28-R31 -> -43.289858 | Q32: Landfill | R32: ='Scope 3 Yearly'!BN12-R28*'Scope 3 Yearly'!BN12/('Scope 3 Yearly'!BN20+'Scope 3 Yearly'!BN12) -> 96.58607 | S32: =R32/SUM($R$35) -> 0.18654164
A33: Note Point source /waste can come from within or other industries | Q33: Leakage | R33: ='Scope 3 Yearly'!BN15+'Scope 3 Yearly'!BN13+'Scope 3 Yearly'!BN16 -> 24.532226 | S33: =R33/SUM($R$35) -> 0.047380349
A34: No quanitfication has been made but it must be shown visually | Q34: Accumulate in the economy | R34: =N27-SUM(R26:R33) -> 143.91733 | S34: =R34/SUM($R$35) -> 0.27795495 | U34: =R34/N28 -> 0.24526608
A35: Number in yellow estimated from the demand model (feedstock in t of C for Ar&Ol excluding hydrogen) | Q35: Total end-of-use | R35: =SUM(R26:R34) -> 517.77216
R36: =B31-SUM(R28:R33) -> 143.91733
A38: Not shown
E39: Elimination | F39: ='Final Exhibits'!G24-'Job + CO2 Analysis'!BN5 -> 134.31279 | G39: =F39/$F$41 -> 0.24174746 | I39: Elimination | J39: =F39 -> 134.31279 | K39: =J39/$J$41 -> 0.18626273 | M39: Elimination | N39: =J39 -> 134.31279 | O39: =N39/$N$41 -> 0.16999435
E40: Substitution | F40: ='Final Exhibits'!H25-'Job + CO2 Analysis'!BN6 -> 69.008255 | G40: =F40/$F$41 -> 0.12420687 | I40: Substitution | J40: =F40 -> 69.008255 | K40: =J40/$J$41 -> 0.095699494 | M40: Substitution | N40: =J40 -> 69.008255 | O40: =N40/$N$41 -> 0.087341004
E41: Total utility: | F41: =SUM(F28:F40) -> 555.59129 | G41: =F41/$F$41 -> 1 | I41: Total utility: | J41: =SUM(J28,J39,J40) -> 721.0932 | K41: =J41/$J$41 -> 1 | M41: Total utility: | N41: =SUM(N28,N39,N40) -> 790.10146 | O41: =N41/$N$41 -> 1
A43: For No fossil after X / Low circularity - 2050
B44: Box #1 Feedstock | F44: Box #2: Chemical Production | J44: Box #3: Product Manufacturing | N44: Box #4: Use Phase | R44: Box #5: End-of-use
B45: Mt in 2050 | C45: % | F45: Mt in 2050 | G45: % | J45: Mt in 2050 | K45: % | N45: Mt in 2050 | O45: % | R45: Mt in 2050 | S45: %
A46: Fossil | B46: =C46*$B$51 -> 69.299148 | C46: 0.17803725 | E46: Depolymerization | F46: =R47 -> 6.3205161 | G46: =F46/$F$28 -> 0.015978649 | I46: Mechanical recycling | J46: =R46 -> 122.21205 | K46: =J46/$J$48 -> 0.23603442 | M46: Resuse | N46: =N26 -> 69.008255 | O46: =N46/$N$28 -> 0.1176049 | Q46: Mechanical recycling | R46: =R26 -> 122.21205 | S46: =R46/SUM($R$35) -> 0.23603442
...

Sheet Final Exhibits
A1: Exhibit 3.1 – without circularity, demand for all base chemicals will increase, particularly methanol and ammonia as they enable a net zero economy
B2: 2020 | C2: Label | D2: 2050 BAU | E2: Label | F2: 2050 decarbonized BAU
A4: Butadiene | B4: ='Yearly Summary'!D57 -> 14.947368 | C4: =D4-B4 -> 10.107591 | D4: ='Yearly Summary'!AH57-E4 -> 25.054959 | E4: ='Yearly Butadiene'!AH42 -> 0 | F4: =D4+E4 -> 25.054959 | L4: Ammonia | M4: Ethylene | N4: Propylene | O4: Methanol | P4: Benzene | Q4: Toluene | R4: Xylene | S4: Butadiene
A5: Xylene | B5: ='Yearly Summary'!D52 -> 50.261625 | C5: =D5-B5 -> 18.121485 | D5: ='Yearly Summary'!AH52-E5 -> 68.38311 | E5: ='Yearly BTX'!AH66+'Yearly BTX'!AH17*'Yearly BTX'!AH24/SUM('Yearly BTX'!AH24:AH26) -> 1.3109583 | F5: =D5+E5 -> 69.694069 | I5: Text | K5: 2020 | L5: =B11 -> 185.16 | M5: =B9 -> 162.69231 | N5: =B8 -> 111.92308 | O5: =B10 -> 101.96027 | P5: =B7 -> 51.832301 | Q5: =B6 -> 14.015261 | R5: =B5 -> 50.261625 | S5: =B4 -> 14.947368
A6: Toluene | B6: ='Yearly Summary'!D47 -> 14.015261 | C6: =D6-B6 -> 5.2596726 | D6: ='Yearly Summary'!AH47-E6 -> 19.274933 | E6: ='Yearly BTX'!AH65+'Yearly BTX'!AH17*'Yearly BTX'!AH25/SUM('Yearly BTX'!AH24:AH26) -> 0.15898954 | F6: =D6+E6 -> 19.433923 | K6: 2050 | L6: =D11 -> 227.54 | M6: =D9 -> 255 | N6: =D8 -> 160 | O6: =D10 -> 145.59946 | P6: =D7 -> 70.854945 | Q6: =D6 -> 19.274933 | R6: =D5 -> 68.38311 | S6: =D4 -> 25.054959
A7: Benzene | B7: ='Yearly Summary'!D42 -> 51.832301 | C7: =D7-B7 -> 19.022644 | D7: ='Yearly Summary'!AH42-E7 -> 70.854945 | E7: ='Yearly BTX'!AH64+'Yearly BTX'!AH17*'Yearly BTX'!AH26/SUM('Yearly BTX'!AH24:AH26) -> 1.017063 | F7: =D7+E7 -> 71.872008 | H7: Total chem 2020 | I7: =SUM(B4:B11) -> 692.79221
A8: Propylene | B8: ='Yearly Summary'!D32 -> 111.92308 | C8: =D8-B8 -> 48.076923 | D8: ='Yearly Summary'!AH32-E8 -> 160 | E8: ='Yearly HC Propylene'!AH41 -> 2.9240993 | F8: =D8+E8 -> 162.9241 | H8: Total chem 2050 | I8: =SUM(D4:D11) -> 971.70741 | K8: R&S&Recycling(mech&chem) | M8: =SUM('Yearly LC Ethylene'!AH81:AH82,'Yearly LC Ethylene'!AH146:AH147,'Yearly LC Ethylene'!AH155:AH156) -> 130.0418 | N8: =SUM('Yearly LC Propylene'!AH39:AH40,'Yearly LC Propylene'!AH66:AH67,'Yearly LC Propylene'!AH69:AH70) -> 68.364855 | S8: =SUM('Yearly Butadiene'!BN43:BN44,'Yearly Butadiene'!BN71:BN72,'Yearly Butadiene'!BN74:BN75) -> 6.6245713
A9: Ethylene | B9: ='Yearly Summary'!D27 -> 162.69231 | C9: =D9-B9 -> 92.307692 | D9: ='Yearly Summary'!AH27-E9 -> 255 | E9: ='Yearly HC Ethylene'!AH83 -> 25.104593 | F9: =D9+E9 -> 280.10459 | H9: CAGR | I9: =(I8/I7)^(1/30)-1 -> 0.011341318 | K9: check | M9: =M6-'Yearly Summary'!BN28-'Final Exhibits'!M8 -> -25.104593 | N9: =N6-'Yearly Summary'!BN33-'Final Exhibits'!N8 -> -2.9240993 | S9: =S6-'Yearly Summary'!BN58-'Final Exhibits'!S8 -> 0
A10: Methanol | B10: ='Yearly Summary'!D37+31 -> 101.96027 | C10: =D10-B10 -> 43.63919 | D10: ='Yearly Summary'!AH37 -> 145.59946 | E10: =290 -> 290 | F10: =D10+E10 -> 435.59946
A11: Ammonia | B11: ='Yearly Summary'!D14 -> 185.16 | C11: =D11-B11 -> 42.38 | D11: 227.54 | E11: 786 | F11: =D11+E11 -> 1013.54
A13: Exhibit 3.2c – without circularity, demand for all base chemicals will increase, particularly methanol and ammonia as they enable a net zero economy
B14: =B2 -> 2020 | C14: =C2 -> Label | D14: =D2 -> 2050 BAU | E14: =E2 -> Label | F14: =F2 -> 2050 decarbonized BAU | G14: Label | I14: Label | J14: Label | K14: 2050 NZ + Low circularity | L14: Label | N14: Label | O14: Label | P14: 2050 NZ + High circularity
A16: Butadiene | B16: =B4 -> 14.947368 | C16: =C4 -> 10.107591 | D16: =D4 -> 25.054959 | E16: =E4 -> 0 | F16: =F4 -> 25.054959 | K16: ='Yearly Summary'!BN58 -> 18.430388 | P16: ='Yearly Summary'!AH58 -> 13.066197 | S16: =E16/F16 -> 0
A17: Xylene | B17: =B5 -> 50.261625 | C17: =C5 -> 18.121485 | D17: =D5 -> 68.38311 | E17: =E5 -> 1.3109583 | F17: =F5 -> 69.694069 | K17: ='Yearly Summary'!BN53 -> 36.996859 | P17: ='Yearly Summary'!AH53 -> 23.482733 | S17: =E17/F17 -> 0.018810185
A18: Toluene | B18: =B6 -> 14.015261 | C18: =C6 -> 5.2596726 | D18: =D6 -> 19.274933 | E18: =E6 -> 0.15898954 | F18: =F6 -> 19.433923 | K18: ='Yearly Summary'!BN48 -> 10.316432 | P18: ='Yearly Summary'!AH48 -> 6.5480698 | S18: =E18/F18 -> 0.0081810316
A19: Benzene | B19: =B7 -> 51.832301 | C19: =C7 -> 19.022644 | D19: =D7 -> 70.854945 | E19: =E7 -> 1.017063 | F19: =F7 -> 71.872008 | K19: ='Yearly Summary'!BN43 -> 38.15301 | P19: ='Yearly Summary'!AH43 -> 24.216568 | S19: =E19/F19 -> 0.014151031
A20: Propylene | B20: =B8 -> 111.92308 | C20: =C8 -> 48.076923 | D20: =D8 -> 160 | E20: =E8 -> 2.9240993 | F20: =F8 -> 162.9241 | K20: ='Yearly Summary'!BN33 -> 94.559244 | P20: ='Yearly Summary'!AH33 -> 72.466496 | S20: =E20/F20 -> 0.017947617
A21: Ethylene | B21: =B9 -> 162.69231 | C21: =C9 -> 92.307692 | D21: =D9 -> 255 | E21: =E9 -> 25.104593 | F21: =F9 -> 280.10459 | K21: ='Yearly Summary'!BN28 -> 150.0628 | P21: ='Yearly Summary'!AH28 -> 95.249512 | S21: =E21/F21 -> 0.089625781
A22: Methanol | B22: =B10 -> 101.96027 | C22: =C10 -> 43.63919 | D22: =D10 -> 145.59946 | E22: =E10 -> 290 | F22: =F10 -> 435.59946 | K22: ='Yearly Summary'!BN38+E10-'Yearly Methanol'!AH71 -> 361.72086 | P22: ='Yearly Summary'!AH38+E10-'Yearly Methanol'!AH71 -> 349.07225
A23: Ammonia | B23: =B11 -> 185.16 | C23: =C11 -> 42.38 | D23: =D11 -> 227.54 | E23: =E11 -> 786 | F23: =D23+E23 -> 1013.54 | K23: ='Yearly Summary'!BN15 -> 995.54 | P23: ='Yearly Summary'!AH15 -> 967.54 | S23: =E23/F23 -> 0.77549973
A24: Elimination | G24: =SUM('Job + CO2 Analysis'!BN5,'Job + CO2 Analysis'!BN7,'Job + CO2 Analysis'!BN8,'Job + CO2 Analysis'!BN13,'Job + CO2 Analysis'!BN14,'Job + CO2 Analysis'!BN16,'Job + CO2 Analysis'!BN19) -> 152.31279 | L24: =SUM('Job + CO2 Analysis'!AH5,'Job + CO2 Analysis'!AH7,'Job + CO2 Analysis'!AH8,'Job + CO2 Analysis'!AH13,'Job + CO2 Analysis'!AH14,'Job + CO2 Analysis'!AH16,'Job + CO2 Analysis'!AH19) -> 246.15143
A25: Reuse | H25: =SUM('Job + CO2 Analysis'!BN9,'Job + CO2 Analysis'!BN12,'Job + CO2 Analysis'!BN17) -> 69.008255 | M25: =SUM('Job + CO2 Analysis'!AH9,'Job + CO2 Analysis'!AH12,'Job + CO2 Analysis'!AH17) -> 104.54799
A26: Substitution | I26: =SUM('Job + CO2 Analysis'!BN6,'Job + CO2 Analysis'!BN10,'Job + CO2 Analysis'!BN11,'Job + CO2 Analysis'!BN15,'Job + CO2 Analysis'!BN18,'Job + CO2 Analysis'!BN20) -> 53.266937 | N26: =SUM('Job + CO2 Analysis'!AH6,'Job + CO2 Analysis'!AH10,'Job + CO2 Analysis'!AH11,'Job + CO2 Analysis'!AH15,'Job + CO2 Analysis'!AH18,'Job + CO2 Analysis'!AH20) -> 75.014287
A27: Recycling | J27: ='Job + CO2 Analysis'!BN22+'Job + CO2 Analysis'!BN23-'Job + CO2 Analysis'!AJ22-'Job + CO2 Analysis'!AJ23 -> 98.21699 | O27: ='Job + CO2 Analysis'!AH22+'Job + CO2 Analysis'!AH23-'Job + CO2 Analysis'!D22-'Job + CO2 Analysis'!D23 -> 101.18589
A28: Series | G28: =G24 -> 152.31279 | L28: =L24 -> 246.15143
A30: Check | B30: =SUM(B16:B23) -> 692.79221 | D30: =SUM(D16:D23) -> 971.70741 | F30: =SUM(F16:F23) -> 2078.2231 | J30: =F30-G24-I26-J27-H25 -> 1705.4181 | K30: =SUM(K16:K23) -> 1705.7796 | O30: =F30-L24-N26-O27-M25 -> 1551.3235 | P30: =SUM(P16:P23) -> 1551.6418
B31: =B30-B23 -> 507.63221 | D31: =D30-D23 -> 744.16741 | F31: ='Yearly Summary'!AH9+'Final Exhibits'!E22 -> 2078.2231
A32: Numbers in the text
A33: Plastic and fetilizer per capita | F33: Mt chemicals | G33: 2161.7746 | H33: HC | I33: LC
A34: Circular levers for all chemicals | H34: =(SUM('Job + CO2 Analysis'!AH5:AH20,'Job + CO2 Analysis'!AH22:AH23)-SUM('Job + CO2 Analysis'!D22:D23))/SUM('Job + CO2 Analysis'!AH4,'Job + CO2 Analysis'!AH21+E10) -> 0.1818654 | I34: =(SUM('Job + CO2 Analysis'!BN5:BN20,'Job + CO2 Analysis'!BN22:BN23)-SUM('Job + CO2 Analysis'!AJ22:AJ23))/SUM('Job + CO2 Analysis'!BN21,'Job + CO2 Analysis'!BN4,E10) -> 0.12867788 | K34: =SUM(L24:O27)/SUM(F16:F23) -> 0.25353371 | L34: =(SUM(G24:J27))/SUM(F16:F23) -> 0.1793864 | M34: Check
A35: Circular levers for carbon-based chemicals | H35: =(SUM('Job + CO2 Analysis'!AH7:AH20,'Job + CO2 Analysis'!AH22:AH23)-SUM('Job + CO2 Analysis'!D22:D23))/SUM(F16:F22) -> 0.45168333 | I35: =(SUM('Job + CO2 Analysis'!BN7:BN20,'Job + CO2 Analysis'!BN22:BN23)-SUM('Job + CO2 Analysis'!AJ22:AJ23))/SUM(F16:F22) -> 0.33324936 | N35: Excld. Recycling | P35: =(SUM('Job + CO2 Analysis'!AH7:AH20))/SUM(F16:F22) -> 0.35664482 | Q35: =(SUM('Job + CO2 Analysis'!BN7:BN20))/SUM(F16:F22) -> 0.24099939
A36: Elimination | G36: =G24/SUM(G24:J27) -> 0.40855889 | I36: =L24/SUM(L24:O27) -> 0.46716952
A37: Reuse | G37: =H25/SUM(G24:J27) -> 0.18510551 | I37: =M25/SUM(L24:O27) -> 0.19842108
A38: Substitution | G38: =I26/SUM(G24:J27) -> 0.14288151 | I38: =N26/SUM(L24:O27) -> 0.14236922
A39: Recycling | G39: =J27/SUM(G24:J27) -> 0.26345408 | I39: =O27/SUM(L24:O27) -> 0.19204018
A40: Ratio mechanical vs total production | G40: =('Job + CO2 Analysis'!BN22-'Job + CO2 Analysis'!AJ22)/SUM(H40) -> 0.23322103 | H40: =F16*SUM('Demand Breakdown - C4'!G18:G20)+SUM(F17:F19)*SUM('Demand Breakdown - BTX'!I20:I22)+D22*SUM('Demand Breakdown - Methanol'!C3:C11)+F20*SUM('Demand Breakdown - Propylene'!C25:C27)+F21*SUM('Demand Breakdown - Ethylene'!C34:C40)-SUM('Job + CO2 Analysis'!BN8:BN18) -> 394.03203 | I40: =('Job + CO2 Analysis'!AH22-'Job + CO2 Analysis'!D22)/SUM(J40) -> 0.31629705 | J40: =F16*SUM('Demand Breakdown - C4'!G18:G20)+SUM(F17:F19)*SUM('Demand Breakdown - BTX'!I20:I22)+D22*SUM('Demand Breakdown - Methanol'!C3:C11)+F20*SUM('Demand Breakdown - Propylene'!C25:C27)+F21*SUM('Demand Breakdown - Ethylene'!C34:C40)-SUM('Job + CO2 Analysis'!AH8:AH18) -> 290.53876
A41: Mechanical Recycling rates | G41: ='Job + CO2 Analysis'!BN22/SUM('Job + CO2 Analysis'!BN22:BN23,'Job + CO2 Analysis'!BN25:BN30) -> 0.32689708 | I41: ='Job + CO2 Analysis'!AH22/SUM('Job + CO2 Analysis'!AH22:AH23,'Job + CO2 Analysis'!AH25:AH30) -> 0.39028517
A42: Open loop out of total recycling | H42: ='Yearly BTX'!BN113+'Yearly Butadiene'!BN71+'Yearly Methanol'!BN114+'Yearly LC Ethylene'!AH146+'Yearly LC Propylene'!AH66 -> 30.745315 | I42: =H42/'Job + CO2 Analysis'!BN22 -> 0.25157351
A45: METHANOL DEMAND
B46: 2020 | C46: Increase in food demand | D46: 2050 BAU | E46: Additional demand | F46: 2050 Net Zero | G46: Reduced demand | H46: 2050 Net Zero + Circular
...

Sheet Job + CO2 Analysis
D1: HIGH CIRCULARITY | AJ1: LOW CIRCULARITY | BP1: BUSINESS-AS-USUAL | CV1: BUSINESS-AS-USUAL MOST ECONOMIC
D2: 2020 | E2: =D2+1 -> 2021 | F2: =E2+1 -> 2022 | G2: =F2+1 -> 2023 | H2: =G2+1 -> 2024 | I2: =H2+1 -> 2025 | J2: =I2+1 -> 2026 | K2: =J2+1 -> 2027 | L2: =K2+1 -> 2028 | ... AH2: =AG2+1 -> 2050 | AJ2: 2020 | AK2: =AJ2+1 -> 2021 | AL2: =AK2+1 -> 2022 | AM2: =AL2+1 -> 2023 | AN2: =AM2+1 -> 2024 | AO2: =AN2+1 -> 2025 | AP2: =AO2+1 -> 2026 | AQ2: =AP2+1 -> 2027 | AR2: =AQ2+1 -> 2028 | ... BN2: =BM2+1 -> 2050 | BP2: 2020 | BQ2: =BP2+1 -> 2021 | BR2: =BQ2+1 -> 2022 | BS2: =BR2+1 -> 2023 | BT2: =BS2+1 -> 2024 | BU2: =BT2+1 -> 2025 | BV2: =BU2+1 -> 2026 | BW2: =BV2+1 -> 2027 | BX2: =BW2+1 -> 2028 | ... CT2: =CS2+1 -> 2050 | CV2: 2020 | CW2: =CV2+1 -> 2021 | CX2: =CW2+1 -> 2022 | CY2: =CX2+1 -> 2023 | CZ2: =CY2+1 -> 2024 | DA2: =CZ2+1 -> 2025 | DB2: =DA2+1 -> 2026 | DC2: =DB2+1 -> 2027 | DD2: =DC2+1 -> 2028 | ... DZ2: =DY2+1 -> 2050
A3: Total
A4: Production BAU | C4: mTons | D4: ='Yearly Summary'!D9 -> 661.79221 | E4: ='Yearly Summary'!E9 -> 685.15794 | F4: ='Yearly Summary'!F9 -> 707.04741 | G4: ='Yearly Summary'!G9 -> 730.06922 | H4: ='Yearly Summary'!H9 -> 752.29039 | I4: ='Yearly Summary'!I9 -> 774.69829 | J4: ='Yearly Summary'!J9 -> 796.32683 | K4: ='Yearly Summary'!K9 -> 819.04538 | ... AH4: ='Yearly Summary'!AH9 -> 1788.2231 | AJ4: ='Yearly Summary'!AJ9 -> 661.79221 | AK4: ='Yearly Summary'!AK9 -> 685.15794 | AL4: ='Yearly Summary'!AL9 -> 707.04741 | AM4: ='Yearly Summary'!AM9 -> 730.06922 | AN4: ='Yearly Summary'!AN9 -> 752.29039 | AO4: ='Yearly Summary'!AO9 -> 774.69829 | AP4: ='Yearly Summary'!AP9 -> 796.32683 | AQ4: ='Yearly Summary'!AQ9 -> 819.04538 | ... BN4: ='Yearly Summary'!BN9 -> 1788.2231 | BP4: =AJ4 -> 661.79221 | BQ4: =AK4 -> 685.15794 | BR4: =AL4 -> 707.04741 | BS4: =AM4 -> 730.06922 | BT4: =AN4 -> 752.29039 | BU4: =AO4 -> 774.69829 | BV4: =AP4 -> 796.32683 | BW4: =AQ4 -> 819.04538 | ... CT4: =BN4 -> 1788.2231 | CV4: =BP4 -> 661.79221 | CW4: =BQ4 -> 685.15794 | CX4: =BR4 -> 707.04741 | CY4: =BS4 -> 730.06922 | CZ4: =BT4 -> 752.29039 | DA4: =BU4 -> 774.69829 | DB4: =BV4 -> 796.32683 | DC4: =BW4 -> 819.04538 | ... DZ4: =CT4 -> 1788.2231
A5: R | B5: Fertilizer reduction (food waste, new tech, diet shift) | C5: mTons | D5: 0 | E5: 1.3016511 | F5: 2.6347665 | G5: 3.9965539 | H5: 5.3873627 | I5: 6.8051382 | J5: 8.2211838 | K5: 9.6512897 | L5: 11.096188 | M5: 12.553309 | N5: 14.019939 | O5: 15.536888 | P5: 17.068964 | Q5: 18.617304 | R5: 20.17825 | S5: 21.754441 | T5: 23.329794 | U5: 24.913579 | V5: 26.506989 | W5: 28.110611 | X5: 29.718123 | Y5: 31.316179 | Z5: 32.923264 | AA5: 34.526231 | AB5: 36.131568 | AC5: 37.742179 | AD5: 39.39173 | AE5: 41.042895 | AF5: 42.696549 | AG5: 44.347974 | AH5: 46 | AJ5: 0 | AK5: 0.50934174 | AL5: 1.0309956 | AM5: 1.5638689 | AN5: 2.1080985 | AO5: 2.6628802 | AP5: 3.216985 | AQ5: 3.7765916 | AR5: 4.3419868 | AS5: 4.9121643 | AT5: 5.4860631 | AU5: 6.0796518 | AV5: 6.6791597 | AW5: 7.2850319 | AX5: 7.8958369 | AY5: 8.5126072 | AZ5: 9.1290498 | BA5: 9.7487916 | BB5: 10.3723 | BC5: 10.999804 | BD5: 11.628831 | BE5: 12.254157 | BF5: 12.883016 | BG5: 13.510264 | BH5: 14.13844 | BI5: 14.768679 | BJ5: 15.414155 | BK5: 16.060263 | BL5: 16.707345 | BM5: 17.353555 | BN5: 18 | BP5: 0 | BQ5: 0 | BR5: 0 | BS5: 0 | BT5: 0 | BU5: 0 | BV5: 0 | BW5: 0 | BX5: 0 | BY5: 0 | BZ5: 0 | CA5: 0 | CB5: 0 | CC5: 0 | CD5: 0 | CE5: 0 | CF5: 0 | CG5: 0 | CH5: 0 | CI5: 0 | CJ5: 0 | CK5: 0 | CL5: 0 | CM5: 0 | CN5: 0 | CO5: 0 | CP5: 0 | CQ5: 0 | CR5: 0 | CS5: 0 | CT5: 0 | CV5: 0 | CW5: 0 | CX5: 0 | CY5: 0 | CZ5: 0 | DA5: 0 | DB5: 0 | DC5: 0 | DD5: 0 | DE5: 0 | DF5: 0 | DG5: 0 | DH5: 0 | DI5: 0 | DJ5: 0 | DK5: 0 | DL5: 0 | DM5: 0 | DN5: 0 | DO5: 0 | DP5: 0 | DQ5: 0 | DR5: 0 | DS5: 0 | DT5: 0 | DU5: 0 | DV5: 0 | DW5: 0 | DX5: 0 | DY5: 0 | DZ5: 0 | EC5: Total demand 2020 | ED5: % of 2020 demand | EE5: Total demand 2050 | EF5: Elimination | EG5: Reuse | EH5: Subsitution | EI5: Recycling | EJ5: Remaining demand | EK5: Elimination | EL5: Reuse | EM5: Subsitution | EN5: Recycling | EO5: Remaining demand
A6: RR | B6: Fertilizer subsitution (Switch to organic farming) | C6: mTons | D6: 0 | E6: 0 | F6: 0 | G6: 0 | H6: 0 | I6: 0 | J6: 0 | K6: 0 | L6: 0 | M6: 0 | N6: 0 | O6: 0 | P6: 0 | Q6: 0 | R6: 0 | S6: 0 | T6: 0 | U6: 0 | V6: 0 | W6: 0 | X6: 0 | Y6: 0 | Z6: 0 | AA6: 0 | AB6: 0 | AC6: 0 | AD6: 0 | AE6: 0 | AF6: 0 | AG6: 0 | AH6: 0 | AJ6: 0 | AK6: 0 | AL6: 0 | AM6: 0 | AN6: 0 | AO6: 0 | AP6: 0 | AQ6: 0 | AR6: 0 | AS6: 0 | AT6: 0 | AU6: 0 | AV6: 0 | AW6: 0 | AX6: 0 | AY6: 0 | AZ6: 0 | BA6: 0 | BB6: 0 | BC6: 0 | BD6: 0 | BE6: 0 | BF6: 0 | BG6: 0 | BH6: 0 | BI6: 0 | BJ6: 0 | BK6: 0 | BL6: 0 | BM6: 0 | BN6: 0 | BP6: 0 | BQ6: 0 | BR6: 0 | BS6: 0 | BT6: 0 | BU6: 0 | BV6: 0 | BW6: 0 | BX6: 0 | BY6: 0 | BZ6: 0 | CA6: 0 | CB6: 0 | CC6: 0 | CD6: 0 | CE6: 0 | CF6: 0 | CG6: 0 | CH6: 0 | CI6: 0 | CJ6: 0 | CK6: 0 | CL6: 0 | CM6: 0 | CN6: 0 | CO6: 0 | CP6: 0 | CQ6: 0 | CR6: 0 | CS6: 0 | CT6: 0 | CV6: 0 | CW6: 0 | CX6: 0 | CY6: 0 | CZ6: 0 | DA6: 0 | DB6: 0 | DC6: 0 | DD6: 0 | DE6: 0 | DF6: 0 | DG6: 0 | DH6: 0 | DI6: 0 | DJ6: 0 | DK6: 0 | DL6: 0 | DM6: 0 | DN6: 0 | DO6: 0 | DP6: 0 | DQ6: 0 | DR6: 0 | DS6: 0 | DT6: 0 | DU6: 0 | DV6: 0 | DW6: 0 | DX6: 0 | DY6: 0 | DZ6: 0 | EB6: Ferti | EC6: 131.90798 | ED6: =EC6/$EC$13 -> 0.19803019 | EE6: 158.18581 | EF6: =AH5 -> 46 | EG6: =AH6 -> 0 | EH6: 0 | EI6: 0 | EJ6: =EE6-SUM(EF6:EI6) -> 112.18581 | EK6: =EF6/$EE6 -> 0.29079726 | EL6: =EG6/$EE6 -> 0 | EM6: =EH6/$EE6 -> 0 | EN6: =EI6/$EE6 -> 0 | EO6: =EJ6/$EE6 -> 0.70920274 | EP6: =EF6/EF$13 -> 0.18687683
A7: R | B7: Fuel additive elimination | C7: mTons | D7: ='Yearly BTX'!D10+'Yearly Methanol'!D12 -> 0 | E7: ='Yearly BTX'!E10+'Yearly Methanol'!E12 -> 0.72809657 | F7: ='Yearly BTX'!F10+'Yearly Methanol'!F12 -> 1.4859786 | G7: ='Yearly BTX'!G10+'Yearly Methanol'!G12 -> 2.2746126 | H7: ='Yearly BTX'!H10+'Yearly Methanol'!H12 -> 3.0949943 | I7: ='Yearly BTX'!I10+'Yearly Methanol'!I12 -> 3.9481484 | J7: ='Yearly BTX'!J10+'Yearly Methanol'!J12 -> 4.8351305 | K7: ='Yearly BTX'!K10+'Yearly Methanol'!K12 -> 5.7570273 | ... AH7: ='Yearly BTX'!AH10+'Yearly Methanol'!AH12 -> 66.071576 | AJ7: ='Yearly BTX'!AJ10+'Yearly Methanol'!AJ12 -> 0 | AK7: ='Yearly BTX'!AK10+'Yearly Methanol'!AK12 -> 0.72809657 | AL7: ='Yearly BTX'!AL10+'Yearly Methanol'!AL12 -> 1.4859786 | AM7: ='Yearly BTX'!AM10+'Yearly Methanol'!AM12 -> 2.2746126 | AN7: ='Yearly BTX'!AN10+'Yearly Methanol'!AN12 -> 3.0949943 | AO7: ='Yearly BTX'!AO10+'Yearly Methanol'!AO12 -> 3.9481484 | AP7: ='Yearly BTX'!AP10+'Yearly Methanol'!AP12 -> 4.8351305 | AQ7: ='Yearly BTX'!AQ10+'Yearly Methanol'!AQ12 -> 5.7570273 | ... BN7: ='Yearly BTX'!BN10+'Yearly Methanol'!BN12 -> 66.071576 | BP7: 0 | BQ7: 0 | BR7: 0 | BS7: 0 | BT7: 0 | BU7: 0 | BV7: 0 | BW7: 0 | BX7: 0 | BY7: 0 | BZ7: 0 | CA7: 0 | CB7: 0 | CC7: 0 | CD7: 0 | CE7: 0 | CF7: 0 | CG7: 0 | CH7: 0 | CI7: 0 | CJ7: 0 | CK7: 0 | CL7: 0 | CM7: 0 | CN7: 0 | CO7: 0 | CP7: 0 | CQ7: 0 | CR7: 0 | CS7: 0 | CT7: 0 | CV7: 0 | CW7: 0 | CX7: 0 | CY7: 0 | CZ7: 0 | DA7: 0 | DB7: 0 | DC7: 0 | DD7: 0 | DE7: 0 | DF7: 0 | DG7: 0 | DH7: 0 | DI7: 0 | DJ7: 0 | DK7: 0 | DL7: 0 | DM7: 0 | DN7: 0 | DO7: 0 | DP7: 0 | DQ7: 0 | DR7: 0 | DS7: 0 | DT7: 0 | DU7: 0 | DV7: 0 | DW7: 0 | DX7: 0 | DY7: 0 | DZ7: 0 | EB7: Pack | EC7: =SUM('R&S - Packaging and hh goods'!I4:O4) -> 187.00627 | ED7: =EC7/$EC$13 -> 0.28074788 | EE7: =SUM('R&S - Packaging and hh goods'!I6:O6) -> 277.98913 | EF7: =AH8 -> 25.978462 | EG7: =AH9 -> 69.542168 | EH7: =AH10+AH11 -> 44.436284 | EI7: =EI16 -> 23.962811 | EJ7: =EE7-SUM(EF7:EI7) -> 114.06941 | EK7: =EF7/$EE7 -> 0.093451357 | EL7: =EG7/$EE7 -> 0.25016146 | EM7: =EH7/$EE7 -> 0.159849 | EN7: =EI7/$EE7 -> 0.086200532 | EO7: =EJ7/$EE7 -> 0.41033765 | EP7: =EF7/EF$13 -> 0.10553853
A8: R | B8: Packaging reduction | C8: mTons | D8: ='Yearly Butadiene'!D19+'Yearly BTX'!D28+'Yearly Methanol'!D30+'Yearly HC Ethylene'!D27+'Yearly HC Propylene'!D15 -> 0 | E8: ='Yearly Butadiene'!E19+'Yearly BTX'!E28+'Yearly Methanol'!E30+'Yearly HC Ethylene'!E27+'Yearly HC Propylene'!E15 -> 0.13488854 | F8: ='Yearly Butadiene'!F19+'Yearly BTX'!F28+'Yearly Methanol'!F30+'Yearly HC Ethylene'!F27+'Yearly HC Propylene'!F15 -> 0.27340018 | G8: ='Yearly Butadiene'!G19+'Yearly BTX'!G28+'Yearly Methanol'!G30+'Yearly HC Ethylene'!G27+'Yearly HC Propylene'!G15 -> 0.41560848 | H8: ='Yearly Butadiene'!H19+'Yearly BTX'!H28+'Yearly Methanol'!H30+'Yearly HC Ethylene'!H27+'Yearly HC Propylene'!H15 -> 0.5615883 | I8: ='Yearly Butadiene'!I19+'Yearly BTX'!I28+'Yearly Methanol'!I30+'Yearly HC Ethylene'!I27+'Yearly HC Propylene'!I15 -> 0.7114159 | J8: ='Yearly Butadiene'!J19+'Yearly BTX'!J28+'Yearly Methanol'!J30+'Yearly HC Ethylene'!J27+'Yearly HC Propylene'!J15 -> 0.8651689 | K8: ='Yearly Butadiene'!K19+'Yearly BTX'!K28+'Yearly Methanol'!K30+'Yearly HC Ethylene'!K27+'Yearly HC Propylene'!K15 -> 1.0229263 | ... AH8: ='Yearly Butadiene'!AH19+'Yearly BTX'!AH28+'Yearly Methanol'!AH30+'Yearly HC Ethylene'!AH27+'Yearly HC Propylene'!AH15 -> 25.978462 | AJ8: ='Yearly Butadiene'!AJ19+'Yearly BTX'!AJ28+'Yearly Methanol'!AJ30+'Yearly LC Ethylene'!D27+'Yearly LC Propylene'!D15 -> 0 | AK8: ='Yearly Butadiene'!AK19+'Yearly BTX'!AK28+'Yearly Methanol'!AK30+'Yearly LC Ethylene'!E27+'Yearly LC Propylene'!E15 -> 0.10007524 | AL8: ='Yearly Butadiene'!AL19+'Yearly BTX'!AL28+'Yearly Methanol'!AL30+'Yearly LC Ethylene'!F27+'Yearly LC Propylene'!F15 -> 0.20284033 | AM8: ='Yearly Butadiene'!AM19+'Yearly BTX'!AM28+'Yearly Methanol'!AM30+'Yearly LC Ethylene'!G27+'Yearly LC Propylene'!G15 -> 0.30834991 | AN8: ='Yearly Butadiene'!AN19+'Yearly BTX'!AN28+'Yearly Methanol'!AN30+'Yearly LC Ethylene'!H27+'Yearly LC Propylene'!H15 -> 0.4166596 | AO8: ='Yearly Butadiene'!AO19+'Yearly BTX'!AO28+'Yearly Methanol'!AO30+'Yearly LC Ethylene'!I27+'Yearly LC Propylene'!I15 -> 0.52782603 | AP8: ='Yearly Butadiene'!AP19+'Yearly BTX'!AP28+'Yearly Methanol'!AP30+'Yearly LC Ethylene'!J27+'Yearly LC Propylene'!J15 -> 0.64190688 | AQ8: ='Yearly Butadiene'!AQ19+'Yearly BTX'!AQ28+'Yearly Methanol'!AQ30+'Yearly LC Ethylene'!K27+'Yearly LC Propylene'!K15 -> 0.75896085 | ... BN8: ='Yearly Butadiene'!BN19+'Yearly BTX'!BN28+'Yearly Methanol'!BN30+'Yearly LC Ethylene'!AH27+'Yearly LC Propylene'!AH15 -> 19.249891 | BP8: 0 | BQ8: 0 | BR8: 0 | BS8: 0 | BT8: 0 | BU8: 0 | BV8: 0 | BW8: 0 | BX8: 0 | BY8: 0 | BZ8: 0 | CA8: 0 | CB8: 0 | CC8: 0 | CD8: 0 | CE8: 0 | CF8: 0 | CG8: 0 | CH8: 0 | CI8: 0 | CJ8: 0 | CK8: 0 | CL8: 0 | CM8: 0 | CN8: 0 | CO8: 0 | CP8: 0 | CQ8: 0 | CR8: 0 | CS8: 0 | CT8: 0 | CV8: 0 | CW8: 0 | CX8: 0 | CY8: 0 | CZ8: 0 | DA8: 0 | DB8: 0 | DC8: 0 | DD8: 0 | DE8: 0 | DF8: 0 | DG8: 0 | DH8: 0 | DI8: 0 | DJ8: 0 | DK8: 0 | DL8: 0 | DM8: 0 | DN8: 0 | DO8: 0 | DP8: 0 | DQ8: 0 | DR8: 0 | DS8: 0 | DT8: 0 | DU8: 0 | DV8: 0 | DW8: 0 | DX8: 0 | DY8: 0 | DZ8: 0 | EB8: Building | EC8: =SUM('R&S - Buildings'!I4:O4) -> 68.497699 | ED8: =EC8/$EC$13 -> 0.1028339 | EE8: =SUM('R&S - Buildings'!I6:O6) -> 109.15985 | EF8: =AH14 -> 58.845444 | EG8: =0 -> 0 | EH8: =AH15 -> 15.817863 | EI8: =EI17 -> 31.002061 | EJ8: =EE8-SUM(EF8:EI8) -> 3.4944848 | EK8: =EF8/$EE8 -> 0.53907588 | EL8: =EG8/$EE8 -> 0 | EM8: =EH8/$EE8 -> 0.1449055 | EN8: =EI8/$EE8 -> 0.28400607 | EO8: =EJ8/$EE8 -> 0.032012546 | EP8: =EF8/EF$13 -> 0.23906196
A9: RR | B9: Packaging reuse | C9: mTons | D9: ='Yearly Butadiene'!D20+'Yearly BTX'!D29+'Yearly Methanol'!D31+'Yearly HC Ethylene'!D28+'Yearly HC Propylene'!D16 -> 0 | E9: ='Yearly Butadiene'!E20+'Yearly BTX'!E29+'Yearly Methanol'!E31+'Yearly HC Ethylene'!E28+'Yearly HC Propylene'!E16 -> 0.96556306 | F9: ='Yearly Butadiene'!F20+'Yearly BTX'!F29+'Yearly Methanol'!F31+'Yearly HC Ethylene'!F28+'Yearly HC Propylene'!F16 -> 1.9563881 | G9: ='Yearly Butadiene'!G20+'Yearly BTX'!G29+'Yearly Methanol'!G31+'Yearly HC Ethylene'!G28+'Yearly HC Propylene'!G16 -> 2.9729764 | H9: ='Yearly Butadiene'!H20+'Yearly BTX'!H29+'Yearly Methanol'!H31+'Yearly HC Ethylene'!H28+'Yearly HC Propylene'!H16 -> 4.0158381 | I9: ='Yearly Butadiene'!I20+'Yearly BTX'!I29+'Yearly Methanol'!I31+'Yearly HC Ethylene'!I28+'Yearly HC Propylene'!I16 -> 5.0854925 | J9: ='Yearly Butadiene'!J20+'Yearly BTX'!J29+'Yearly Methanol'!J31+'Yearly HC Ethylene'!J28+'Yearly HC Propylene'!J16 -> 6.1824679 | K9: ='Yearly Butadiene'!K20+'Yearly BTX'!K29+'Yearly Methanol'!K31+'Yearly HC Ethylene'!K28+'Yearly HC Propylene'!K16 -> 7.3073023 | ... AH9: ='Yearly Butadiene'!AH20+'Yearly BTX'!AH29+'Yearly Methanol'!AH31+'Yearly HC Ethylene'!AH28+'Yearly HC Propylene'!AH16 -> 69.542168 | AJ9: ='Yearly Butadiene'!AJ20+'Yearly BTX'!AJ29+'Yearly Methanol'!AJ31+'Yearly LC Ethylene'!D28+'Yearly LC Propylene'!D16 -> 0 | AK9: ='Yearly Butadiene'!AK20+'Yearly BTX'!AK29+'Yearly Methanol'!AK31+'Yearly LC Ethylene'!E28+'Yearly LC Propylene'!E16 -> 0.71567648 | AL9: ='Yearly Butadiene'!AL20+'Yearly BTX'!AL29+'Yearly Methanol'!AL31+'Yearly LC Ethylene'!F28+'Yearly LC Propylene'!F16 -> 1.4500971 | AM9: ='Yearly Butadiene'!AM20+'Yearly BTX'!AM29+'Yearly Methanol'!AM31+'Yearly LC Ethylene'!G28+'Yearly LC Propylene'!G16 -> 2.203634 | AN9: ='Yearly Butadiene'!AN20+'Yearly BTX'!AN29+'Yearly Methanol'!AN31+'Yearly LC Ethylene'!H28+'Yearly LC Propylene'!H16 -> 2.9766662 | AO9: ='Yearly Butadiene'!AO20+'Yearly BTX'!AO29+'Yearly Methanol'!AO31+'Yearly LC Ethylene'!I28+'Yearly LC Propylene'!I16 -> 3.7695793 | AP9: ='Yearly Butadiene'!AP20+'Yearly BTX'!AP29+'Yearly Methanol'!AP31+'Yearly LC Ethylene'!J28+'Yearly LC Propylene'!J16 -> 4.5827658 | AQ9: ='Yearly Butadiene'!AQ20+'Yearly BTX'!AQ29+'Yearly Methanol'!AQ31+'Yearly LC Ethylene'!K28+'Yearly LC Propylene'!K16 -> 5.4166252 | ... BN9: ='Yearly Butadiene'!BN20+'Yearly BTX'!BN29+'Yearly Methanol'!BN31+'Yearly LC Ethylene'!AH28+'Yearly LC Propylene'!AH16 -> 51.505343 | BP9: 0 | BQ9: 0 | BR9: 0 | BS9: 0 | BT9: 0 | BU9: 0 | BV9: 0 | BW9: 0 | BX9: 0 | BY9: 0 | BZ9: 0 | CA9: 0 | CB9: 0 | CC9: 0 | CD9: 0 | CE9: 0 | CF9: 0 | CG9: 0 | CH9: 0 | CI9: 0 | CJ9: 0 | CK9: 0 | CL9: 0 | CM9: 0 | CN9: 0 | CO9: 0 | CP9: 0 | CQ9: 0 | CR9: 0 | CS9: 0 | CT9: 0 | CV9: 0 | CW9: 0 | CX9: 0 | CY9: 0 | CZ9: 0 | DA9: 0 | DB9: 0 | DC9: 0 | DD9: 0 | DE9: 0 | DF9: 0 | DG9: 0 | DH9: 0 | DI9: 0 | DJ9: 0 | DK9: 0 | DL9: 0 | DM9: 0 | DN9: 0 | DO9: 0 | DP9: 0 | DQ9: 0 | DR9: 0 | DS9: 0 | DT9: 0 | DU9: 0 | DV9: 0 | DW9: 0 | DX9: 0 | DY9: 0 | DZ9: 0 | EB9: Transport | EC9: =SUM('R&S - Transportation'!C4:K4) -> 106.90047 | ED9: =EC9/$EC$13 -> 0.16048703 | EE9: =SUM('R&S - Transportation'!C7:J7) -> 135.62387 | EF9: =AH13 -> 13.627368 | EG9: =AH12 -> 26.601184 | EH9: =0 -> 0 | EI9: =EI18 -> 10.117577 | EJ9: =EE9-SUM(EF9:EI9) -> 85.277744 | EK9: =EF9/$EE9 -> 0.10047913 | EL9: =EG9/$EE9 -> 0.19613939 | EM9: =EH9/$EE9 -> 0 | EN9: =EI9/$EE9 -> 0.074600265 | EO9: =EJ9/$EE9 -> 0.62878122 | EP9: =EF9/EF$13 -> 0.055361726
A10: S | B10: Packaging substitution Paper | C10: mTons | D10: ='Yearly Butadiene'!D22+'Yearly BTX'!D31+'Yearly Methanol'!D33+'Yearly HC Ethylene'!D30+'Yearly HC Propylene'!D18 -> 0 | E10: ='Yearly Butadiene'!E22+'Yearly BTX'!E31+'Yearly Methanol'!E33+'Yearly HC Ethylene'!E30+'Yearly HC Propylene'!E18 -> 0.36852278 | F10: ='Yearly Butadiene'!F22+'Yearly BTX'!F31+'Yearly Methanol'!F33+'Yearly HC Ethylene'!F30+'Yearly HC Propylene'!F18 -> 0.74682926 | G10: ='Yearly Butadiene'!G22+'Yearly BTX'!G31+'Yearly Methanol'!G33+'Yearly HC Ethylene'!G30+'Yearly HC Propylene'!G18 -> 1.1351161 | H10: ='Yearly Butadiene'!H22+'Yearly BTX'!H31+'Yearly Methanol'!H33+'Yearly HC Ethylene'!H30+'Yearly HC Propylene'!H18 -> 1.5335834 | I10: ='Yearly Butadiene'!I22+'Yearly BTX'!I31+'Yearly Methanol'!I33+'Yearly HC Ethylene'!I30+'Yearly HC Propylene'!I18 -> 1.9424351 | J10: ='Yearly Butadiene'!J22+'Yearly BTX'!J31+'Yearly Methanol'!J33+'Yearly HC Ethylene'!J30+'Yearly HC Propylene'!J18 -> 2.3618784 | K10: ='Yearly Butadiene'!K22+'Yearly BTX'!K31+'Yearly Methanol'!K33+'Yearly HC Ethylene'!K30+'Yearly HC Propylene'!K18 -> 2.7921247 | ... AH10: ='Yearly Butadiene'!AH22+'Yearly BTX'!AH31+'Yearly Methanol'!AH33+'Yearly HC Ethylene'!AH30+'Yearly HC Propylene'!AH18 -> 19.174076 | AJ10: ='Yearly Butadiene'!AJ22+'Yearly BTX'!AJ31+'Yearly Methanol'!AJ33+'Yearly LC Ethylene'!D30+'Yearly LC Propylene'!D18 -> 0 | AK10: ='Yearly Butadiene'!AK22+'Yearly BTX'!AK31+'Yearly Methanol'!AK33+'Yearly LC Ethylene'!E30+'Yearly LC Propylene'!E18 -> 0.31520719 | AL10: ='Yearly Butadiene'!AL22+'Yearly BTX'!AL31+'Yearly Methanol'!AL33+'Yearly LC Ethylene'!F30+'Yearly LC Propylene'!F18 -> 0.638804 | AM10: ='Yearly Butadiene'!AM22+'Yearly BTX'!AM31+'Yearly Methanol'!AM33+'Yearly LC Ethylene'!G30+'Yearly LC Propylene'!G18 -> 0.9709594 | AN10: ='Yearly Butadiene'!AN22+'Yearly BTX'!AN31+'Yearly Methanol'!AN33+'Yearly LC Ethylene'!H30+'Yearly LC Propylene'!H18 -> 1.3118454 | AO10: ='Yearly Butadiene'!AO22+'Yearly BTX'!AO31+'Yearly Methanol'!AO33+'Yearly LC Ethylene'!I30+'Yearly LC Propylene'!I18 -> 1.6616373 | AP10: ='Yearly Butadiene'!AP22+'Yearly BTX'!AP31+'Yearly Methanol'!AP33+'Yearly LC Ethylene'!J30+'Yearly LC Propylene'!J18 -> 2.0205131 | AQ10: ='Yearly Butadiene'!AQ22+'Yearly BTX'!AQ31+'Yearly Methanol'!AQ33+'Yearly LC Ethylene'!K30+'Yearly LC Propylene'!K18 -> 2.3886545 | ... BN10: ='Yearly Butadiene'!BN22+'Yearly BTX'!BN31+'Yearly Methanol'!BN33+'Yearly LC Ethylene'!AH30+'Yearly LC Propylene'!AH18 -> 16.374023 | BP10: 0 | BQ10: 0 | BR10: 0 | BS10: 0 | BT10: 0 | BU10: 0 | BV10: 0 | BW10: 0 | BX10: 0 | BY10: 0 | BZ10: 0 | CA10: 0 | CB10: 0 | CC10: 0 | CD10: 0 | CE10: 0 | CF10: 0 | CG10: 0 | CH10: 0 | CI10: 0 | CJ10: 0 | CK10: 0 | CL10: 0 | CM10: 0 | CN10: 0 | CO10: 0 | CP10: 0 | CQ10: 0 | CR10: 0 | CS10: 0 | CT10: 0 | CV10: 0 | CW10: 0 | CX10: 0 | CY10: 0 | CZ10: 0 | DA10: 0 | DB10: 0 | DC10: 0 | DD10: 0 | DE10: 0 | DF10: 0 | DG10: 0 | DH10: 0 | DI10: 0 | DJ10: 0 | DK10: 0 | DL10: 0 | DM10: 0 | DN10: 0 | DO10: 0 | DP10: 0 | DQ10: 0 | DR10: 0 | DS10: 0 | DT10: 0 | DU10: 0 | DV10: 0 | DW10: 0 | DX10: 0 | DY10: 0 | DZ10: 0 | EB10: Fashion | EC10: ='Demand - Industry shares'!L16 -> 83.333906 | ED10: =EC10/$EC$13 -> 0.12510713 | EE10: =SUM('R&S - Apparel'!D6:J6) -> 24.934953 | EF10: =AH16 -> 6.1798822 | EG10: =AH17 -> 8.4046398 | EH10: =AH18 -> 4.9439058 | EI10: =EI19 -> 1.6046712 | EJ10: =EE10-SUM(EF10:EI10) -> 3.8018537 | EK10: =EF10/$EE10 -> 0.24784014 | EL10: =EG10/$EE10 -> 0.33706259 | EM10: =EH10/$EE10 -> 0.19827211 | EN10: =EI10/$EE10 -> 0.064354291 | EO10: =EJ10/$EE10 -> 0.15247086 | EP10: =EF10/EF$13 -> 0.025106017
A11: S | B11: Packaging Substitution Compostables | C11: mTons | D11: ='Yearly Butadiene'!D23+'Yearly BTX'!D32+'Yearly Methanol'!D34+'Yearly HC Ethylene'!D31+'Yearly HC Propylene'!D19 -> 0 | E11: ='Yearly Butadiene'!E23+'Yearly BTX'!E32+'Yearly Methanol'!E34+'Yearly HC Ethylene'!E31+'Yearly HC Propylene'!E19 -> 0.39153935 | F11: ='Yearly Butadiene'!F23+'Yearly BTX'!F32+'Yearly Methanol'!F34+'Yearly HC Ethylene'!F31+'Yearly HC Propylene'!F19 -> 1.0124569 | G11: ='Yearly Butadiene'!G23+'Yearly BTX'!G32+'Yearly Methanol'!G34+'Yearly HC Ethylene'!G31+'Yearly HC Propylene'!G19 -> 1.5389624 | H11: ='Yearly Butadiene'!H23+'Yearly BTX'!H32+'Yearly Methanol'!H34+'Yearly HC Ethylene'!H31+'Yearly HC Propylene'!H19 -> 2.0793499 | I11: ='Yearly Butadiene'!I23+'Yearly BTX'!I32+'Yearly Methanol'!I34+'Yearly HC Ethylene'!I31+'Yearly HC Propylene'!I19 -> 2.6338987 | J11: ='Yearly Butadiene'!J23+'Yearly BTX'!J32+'Yearly Methanol'!J34+'Yearly HC Ethylene'!J31+'Yearly HC Propylene'!J19 -> 3.202893 | K11: ='Yearly Butadiene'!K23+'Yearly BTX'!K32+'Yearly Methanol'!K34+'Yearly HC Ethylene'!K31+'Yearly HC Propylene'!K19 -> 3.7866222 | ... AH11: ='Yearly Butadiene'!AH23+'Yearly BTX'!AH32+'Yearly Methanol'!AH34+'Yearly HC Ethylene'!AH31+'Yearly HC Propylene'!AH19 -> 25.262208 | AJ11: ='Yearly Butadiene'!AJ23+'Yearly BTX'!AJ32+'Yearly Methanol'!AJ34+'Yearly LC Ethylene'!D31+'Yearly LC Propylene'!D19 -> 0 | AK11: ='Yearly Butadiene'!AK23+'Yearly BTX'!AK32+'Yearly Methanol'!AK34+'Yearly LC Ethylene'!E31+'Yearly LC Propylene'!E19 -> 0.34007706 | AL11: ='Yearly Butadiene'!AL23+'Yearly BTX'!AL32+'Yearly Methanol'!AL34+'Yearly LC Ethylene'!F31+'Yearly LC Propylene'!F19 -> 0.86853882 | AM11: ='Yearly Butadiene'!AM23+'Yearly BTX'!AM32+'Yearly Methanol'!AM34+'Yearly LC Ethylene'!G31+'Yearly LC Propylene'!G19 -> 1.3202415 | AN11: ='Yearly Butadiene'!AN23+'Yearly BTX'!AN32+'Yearly Methanol'!AN34+'Yearly LC Ethylene'!H31+'Yearly LC Propylene'!H19 -> 1.7838801 | AO11: ='Yearly Butadiene'!AO23+'Yearly BTX'!AO32+'Yearly Methanol'!AO34+'Yearly LC Ethylene'!I31+'Yearly LC Propylene'!I19 -> 2.259695 | AP11: ='Yearly Butadiene'!AP23+'Yearly BTX'!AP32+'Yearly Methanol'!AP34+'Yearly LC Ethylene'!J31+'Yearly LC Propylene'!J19 -> 2.747931 | AQ11: ='Yearly Butadiene'!AQ23+'Yearly BTX'!AQ32+'Yearly Methanol'!AQ34+'Yearly LC Ethylene'!K31+'Yearly LC Propylene'!K19 -> 3.2488376 | ... BN11: ='Yearly Butadiene'!BN23+'Yearly BTX'!BN32+'Yearly Methanol'!BN34+'Yearly LC Ethylene'!AH31+'Yearly LC Propylene'!AH19 -> 21.603912 | BP11: 0 | BQ11: 0 | BR11: 0 | BS11: 0 | BT11: 0 | BU11: 0 | BV11: 0 | BW11: 0 | BX11: 0 | BY11: 0 | BZ11: 0 | CA11: 0 | CB11: 0 | CC11: 0 | CD11: 0 | CE11: 0 | CF11: 0 | CG11: 0 | CH11: 0 | CI11: 0 | CJ11: 0 | CK11: 0 | CL11: 0 | CM11: 0 | CN11: 0 | CO11: 0 | CP11: 0 | CQ11: 0 | CR11: 0 | CS11: 0 | CT11: 0 | CV11: 0 | CW11: 0 | CX11: 0 | CY11: 0 | CZ11: 0 | DA11: 0 | DB11: 0 | DC11: 0 | DD11: 0 | DE11: 0 | DF11: 0 | DG11: 0 | DH11: 0 | DI11: 0 | DJ11: 0 | DK11: 0 | DL11: 0 | DM11: 0 | DN11: 0 | DO11: 0 | DP11: 0 | DQ11: 0 | DR11: 0 | DS11: 0 | DT11: 0 | DU11: 0 | DV11: 0 | DW11: 0 | DX11: 0 | DY11: 0 | DZ11: 0 | EB11: Additives | ED11: =EC11/$EC$13 -> 0 | EF11: =AH7 -> 66.071576 | EP11: =EF11/EF$13 -> 0.26841841
A12: RR | B12: MaaS | C12: mTons | D12: ='Yearly Butadiene'!D13+'Yearly BTX'!D19+'Yearly Methanol'!D21+'Yearly HC Ethylene'!D15+'Yearly HC Propylene'!D9 -> 0 | E12: ='Yearly Butadiene'!E13+'Yearly BTX'!E19+'Yearly Methanol'!E21+'Yearly HC Ethylene'!E15+'Yearly HC Propylene'!E9 -> 0.15528409 | F12: ='Yearly Butadiene'!F13+'Yearly BTX'!F19+'Yearly Methanol'!F21+'Yearly HC Ethylene'!F15+'Yearly HC Propylene'!F9 -> 0.31603763 | G12: ='Yearly Butadiene'!G13+'Yearly BTX'!G19+'Yearly Methanol'!G21+'Yearly HC Ethylene'!G15+'Yearly HC Propylene'!G9 -> 0.48240608 | H12: ='Yearly Butadiene'!H13+'Yearly BTX'!H19+'Yearly Methanol'!H21+'Yearly HC Ethylene'!H15+'Yearly HC Propylene'!H9 -> 0.65453837 | I12: ='Yearly Butadiene'!I13+'Yearly BTX'!I19+'Yearly Methanol'!I21+'Yearly HC Ethylene'!I15+'Yearly HC Propylene'!I9 -> 0.83258694 | J12: ='Yearly Butadiene'!J13+'Yearly BTX'!J19+'Yearly Methanol'!J21+'Yearly HC Ethylene'!J15+'Yearly HC Propylene'!J9 -> 1.0167079 | K12: ='Yearly Butadiene'!K13+'Yearly BTX'!K19+'Yearly Methanol'!K21+'Yearly HC Ethylene'!K15+'Yearly HC Propylene'!K9 -> 1.2070609 | ... AH12: ='Yearly Butadiene'!AH13+'Yearly BTX'!AH19+'Yearly Methanol'!AH21+'Yearly HC Ethylene'!AH15+'Yearly HC Propylene'!AH9 -> 26.601184 | AJ12: ='Yearly Butadiene'!AJ13+'Yearly BTX'!AJ19+'Yearly Methanol'!AJ21+'Yearly LC Ethylene'!D15+'Yearly LC Propylene'!D9 -> 0 | AK12: ='Yearly Butadiene'!AK13+'Yearly BTX'!AK19+'Yearly Methanol'!AK21+'Yearly LC Ethylene'!E15+'Yearly LC Propylene'!E9 -> 0.077598225 | AL12: ='Yearly Butadiene'!AL13+'Yearly BTX'!AL19+'Yearly Methanol'!AL21+'Yearly LC Ethylene'!F15+'Yearly LC Propylene'!F9 -> 0.15784056 | AM12: ='Yearly Butadiene'!AM13+'Yearly BTX'!AM19+'Yearly Methanol'!AM21+'Yearly LC Ethylene'!G15+'Yearly LC Propylene'!G9 -> 0.24079516 | AN12: ='Yearly Butadiene'!AN13+'Yearly BTX'!AN19+'Yearly Methanol'!AN21+'Yearly LC Ethylene'!H15+'Yearly LC Propylene'!H9 -> 0.32653173 | AO12: ='Yearly Butadiene'!AO13+'Yearly BTX'!AO19+'Yearly Methanol'!AO21+'Yearly LC Ethylene'!I15+'Yearly LC Propylene'!I9 -> 0.41512161 | AP12: ='Yearly Butadiene'!AP13+'Yearly BTX'!AP19+'Yearly Methanol'!AP21+'Yearly LC Ethylene'!J15+'Yearly LC Propylene'!J9 -> 0.50663777 | AQ12: ='Yearly Butadiene'!AQ13+'Yearly BTX'!AQ19+'Yearly Methanol'!AQ21+'Yearly LC Ethylene'!K15+'Yearly LC Propylene'!K9 -> 0.60115484 | ... BN12: ='Yearly Butadiene'!BN13+'Yearly BTX'!BN19+'Yearly Methanol'!BN21+'Yearly LC Ethylene'!AH15+'Yearly LC Propylene'!AH9 -> 13.300592 | BP12: 0 | BQ12: 0 | BR12: 0 | BS12: 0 | BT12: 0 | BU12: 0 | BV12: 0 | BW12: 0 | BX12: 0 | BY12: 0 | BZ12: 0 | CA12: 0 | CB12: 0 | CC12: 0 | CD12: 0 | CE12: 0 | CF12: 0 | CG12: 0 | CH12: 0 | CI12: 0 | CJ12: 0 | CK12: 0 | CL12: 0 | CM12: 0 | CN12: 0 | CO12: 0 | CP12: 0 | CQ12: 0 | CR12: 0 | CS12: 0 | CT12: 0 | CV12: 0 | CW12: 0 | CX12: 0 | CY12: 0 | CZ12: 0 | DA12: 0 | DB12: 0 | DC12: 0 | DD12: 0 | DE12: 0 | DF12: 0 | DG12: 0 | DH12: 0 | DI12: 0 | DJ12: 0 | DK12: 0 | DL12: 0 | DM12: 0 | DN12: 0 | DO12: 0 | DP12: 0 | DQ12: 0 | DR12: 0 | DS12: 0 | DT12: 0 | DU12: 0 | DV12: 0 | DW12: 0 | DX12: 0 | DY12: 0 | DZ12: 0 | EB12: Others | EC12: 88.454043 | ED12: =EC12/$EC$13 -> 0.13279387 | EF12: =AH19 -> 29.448703 | EP12: =EF12/EF$13 -> 0.11963653
A13: R | B13: Vehicle life extension | C13: mTons | D13: ='Yearly Butadiene'!D14+'Yearly BTX'!D20+'Yearly Methanol'!D22+'Yearly HC Ethylene'!D16+'Yearly HC Propylene'!D10 -> 0 | E13: ='Yearly Butadiene'!E14+'Yearly BTX'!E20+'Yearly Methanol'!E22+'Yearly HC Ethylene'!E16+'Yearly HC Propylene'!E10 -> 0.098632742 | F13: ='Yearly Butadiene'!F14+'Yearly BTX'!F20+'Yearly Methanol'!F22+'Yearly HC Ethylene'!F16+'Yearly HC Propylene'!F10 -> 0.20036321 | G13: ='Yearly Butadiene'!G14+'Yearly BTX'!G20+'Yearly Methanol'!G22+'Yearly HC Ethylene'!G16+'Yearly HC Propylene'!G10 -> 0.3052623 | H13: ='Yearly Butadiene'!H14+'Yearly BTX'!H20+'Yearly Methanol'!H22+'Yearly HC Ethylene'!H16+'Yearly HC Propylene'!H10 -> 0.41340234 | I13: ='Yearly Butadiene'!I14+'Yearly BTX'!I20+'Yearly Methanol'!I22+'Yearly HC Ethylene'!I16+'Yearly HC Propylene'!I10 -> 0.52485704 | J13: ='Yearly Butadiene'!J14+'Yearly BTX'!J20+'Yearly Methanol'!J22+'Yearly HC Ethylene'!J16+'Yearly HC Propylene'!J10 -> 0.63970154 | K13: ='Yearly Butadiene'!K14+'Yearly BTX'!K20+'Yearly Methanol'!K22+'Yearly HC Ethylene'!K16+'Yearly HC Propylene'!K10 -> 0.75801245 | ... AH13: ='Yearly Butadiene'!AH14+'Yearly BTX'!AH20+'Yearly Methanol'!AH22+'Yearly HC Ethylene'!AH16+'Yearly HC Propylene'!AH10 -> 13.627368 | AJ13: ='Yearly Butadiene'!AJ14+'Yearly BTX'!AJ20+'Yearly Methanol'!AJ22+'Yearly LC Ethylene'!D16+'Yearly LC Propylene'!D10 -> 0 | AK13: ='Yearly Butadiene'!AK14+'Yearly BTX'!AK20+'Yearly Methanol'!AK22+'Yearly LC Ethylene'!E16+'Yearly LC Propylene'!E10 -> 0.049334634 | AL13: ='Yearly Butadiene'!AL14+'Yearly BTX'!AL20+'Yearly Methanol'!AL22+'Yearly LC Ethylene'!F16+'Yearly LC Propylene'!F10 -> 0.10025646 | AM13: ='Yearly Butadiene'!AM14+'Yearly BTX'!AM20+'Yearly Methanol'!AM22+'Yearly LC Ethylene'!G16+'Yearly LC Propylene'!G10 -> 0.15280372 | AN13: ='Yearly Butadiene'!AN14+'Yearly BTX'!AN20+'Yearly Methanol'!AN22+'Yearly LC Ethylene'!H16+'Yearly LC Propylene'!H10 -> 0.2070155 | AO13: ='Yearly Butadiene'!AO14+'Yearly BTX'!AO20+'Yearly Methanol'!AO22+'Yearly LC Ethylene'!I16+'Yearly LC Propylene'!I10 -> 0.2629317 | AP13: ='Yearly Butadiene'!AP14+'Yearly BTX'!AP20+'Yearly Methanol'!AP22+'Yearly LC Ethylene'!J16+'Yearly LC Propylene'!J10 -> 0.32059307 | AQ13: ='Yearly Butadiene'!AQ14+'Yearly BTX'!AQ20+'Yearly Methanol'!AQ22+'Yearly LC Ethylene'!K16+'Yearly LC Propylene'!K10 -> 0.38004124 | ... BN13: ='Yearly Butadiene'!BN14+'Yearly BTX'!BN20+'Yearly Methanol'!BN22+'Yearly LC Ethylene'!AH16+'Yearly LC Propylene'!AH10 -> 7.6388486 | BP13: 0 | BQ13: 0 | BR13: 0 | BS13: 0 | BT13: 0 | BU13: 0 | BV13: 0 | BW13: 0 | BX13: 0 | BY13: 0 | BZ13: 0 | CA13: 0 | CB13: 0 | CC13: 0 | CD13: 0 | CE13: 0 | CF13: 0 | CG13: 0 | CH13: 0 | CI13: 0 | CJ13: 0 | CK13: 0 | CL13: 0 | CM13: 0 | CN13: 0 | CO13: 0 | CP13: 0 | CQ13: 0 | CR13: 0 | CS13: 0 | CT13: 0 | CV13: 0 | CW13: 0 | CX13: 0 | CY13: 0 | CZ13: 0 | DA13: 0 | DB13: 0 | DC13: 0 | DD13: 0 | DE13: 0 | DF13: 0 | DG13: 0 | DH13: 0 | DI13: 0 | DJ13: 0 | DK13: 0 | DL13: 0 | DM13: 0 | DN13: 0 | DO13: 0 | DP13: 0 | DQ13: 0 | DR13: 0 | DS13: 0 | DT13: 0 | DU13: 0 | DV13: 0 | DW13: 0 | DX13: 0 | DY13: 0 | DZ13: 0 | EC13: =SUM(EC6:EC12) -> 666.10037 | EF13: =SUM(EF6:EF12) -> 246.15143 | EP13: =EF13/EF$13 -> 1
A14: R | B14: Building reduction | C14: mTons | D14: ='Yearly Butadiene'!D27+'Yearly BTX'!D39+'Yearly Methanol'!D41+'Yearly HC Ethylene'!D41+'Yearly HC Propylene'!D23 -> 0 | E14: ='Yearly Butadiene'!E27+'Yearly BTX'!E39+'Yearly Methanol'!E41+'Yearly HC Ethylene'!E41+'Yearly HC Propylene'!E23 -> 1.2365128 | F14: ='Yearly Butadiene'!F27+'Yearly BTX'!F39+'Yearly Methanol'!F41+'Yearly HC Ethylene'!F41+'Yearly HC Propylene'!F23 -> 2.5116116 | G14: ='Yearly Butadiene'!G27+'Yearly BTX'!G39+'Yearly Methanol'!G41+'Yearly HC Ethylene'!G41+'Yearly HC Propylene'!G23 -> 3.8262225 | H14: ='Yearly Butadiene'!H27+'Yearly BTX'!H39+'Yearly Methanol'!H41+'Yearly HC Ethylene'!H41+'Yearly HC Propylene'!H23 -> 5.1812918 | I14: ='Yearly Butadiene'!I27+'Yearly BTX'!I39+'Yearly Methanol'!I41+'Yearly HC Ethylene'!I41+'Yearly HC Propylene'!I23 -> 6.5777866 | J14: ='Yearly Butadiene'!J27+'Yearly BTX'!J39+'Yearly Methanol'!J41+'Yearly HC Ethylene'!J41+'Yearly HC Propylene'!J23 -> 8.0166946 | K14: ='Yearly Butadiene'!K27+'Yearly BTX'!K39+'Yearly Methanol'!K41+'Yearly HC Ethylene'!K41+'Yearly HC Propylene'!K23 -> 9.4990251 | ... AH14: ='Yearly Butadiene'!AH27+'Yearly BTX'!AH39+'Yearly Methanol'!AH41+'Yearly HC Ethylene'!AH41+'Yearly HC Propylene'!AH23 -> 58.845444 | AJ14: ='Yearly Butadiene'!AJ27+'Yearly BTX'!AJ39+'Yearly Methanol'!AJ41+'Yearly LC Ethylene'!D41+'Yearly LC Propylene'!D23 -> 0 | AK14: ='Yearly Butadiene'!AK27+'Yearly BTX'!AK39+'Yearly Methanol'!AK41+'Yearly LC Ethylene'!E41+'Yearly LC Propylene'!E23 -> 0.49460513 | AL14: ='Yearly Butadiene'!AL27+'Yearly BTX'!AL39+'Yearly Methanol'!AL41+'Yearly LC Ethylene'!F41+'Yearly LC Propylene'!F23 -> 1.0046446 | AM14: ='Yearly Butadiene'!AM27+'Yearly BTX'!AM39+'Yearly Methanol'!AM41+'Yearly LC Ethylene'!G41+'Yearly LC Propylene'!G23 -> 1.530489 | AN14: ='Yearly Butadiene'!AN27+'Yearly BTX'!AN39+'Yearly Methanol'!AN41+'Yearly LC Ethylene'!H41+'Yearly LC Propylene'!H23 -> 2.0725167 | AO14: ='Yearly Butadiene'!AO27+'Yearly BTX'!AO39+'Yearly Methanol'!AO41+'Yearly LC Ethylene'!I41+'Yearly LC Propylene'!I23 -> 2.6311146 | AP14: ='Yearly Butadiene'!AP27+'Yearly BTX'!AP39+'Yearly Methanol'!AP41+'Yearly LC Ethylene'!J41+'Yearly LC Propylene'!J23 -> 3.2066778 | AQ14: ='Yearly Butadiene'!AQ27+'Yearly BTX'!AQ39+'Yearly Methanol'!AQ41+'Yearly LC Ethylene'!K41+'Yearly LC Propylene'!K23 -> 3.79961 | ... BN14: ='Yearly Butadiene'!BN27+'Yearly BTX'!BN39+'Yearly Methanol'!BN41+'Yearly LC Ethylene'!AH41+'Yearly LC Propylene'!AH23 -> 23.538177 | BP14: 0 | BQ14: 0 | BR14: 0 | BS14: 0 | BT14: 0 | BU14: 0 | BV14: 0 | BW14: 0 | BX14: 0 | BY14: 0 | BZ14: 0 | CA14: 0 | CB14: 0 | CC14: 0 | CD14: 0 | CE14: 0 | CF14: 0 | CG14: 0 | CH14: 0 | CI14: 0 | CJ14: 0 | CK14: 0 | CL14: 0 | CM14: 0 | CN14: 0 | CO14: 0 | CP14: 0 | CQ14: 0 | CR14: 0 | CS14: 0 | CT14: 0 | CV14: 0 | CW14: 0 | CX14: 0 | CY14: 0 | CZ14: 0 | DA14: 0 | DB14: 0 | DC14: 0 | DD14: 0 | DE14: 0 | DF14: 0 | DG14: 0 | DH14: 0 | DI14: 0 | DJ14: 0 | DK14: 0 | DL14: 0 | DM14: 0 | DN14: 0 | DO14: 0 | DP14: 0 | DQ14: 0 | DR14: 0 | DS14: 0 | DT14: 0 | DU14: 0 | DV14: 0 | DW14: 0 | DX14: 0 | DY14: 0 | DZ14: 0 | EC14: =SUM('Yearly Summary'!D9) -> 661.79221
A15: S | B15: Building substitution | C15: mTons | D15: ='Yearly Butadiene'!D28+'Yearly BTX'!D40+'Yearly Methanol'!D42+'Yearly HC Ethylene'!D42+'Yearly HC Propylene'!D24 -> 0 | E15: ='Yearly Butadiene'!E28+'Yearly BTX'!E40+'Yearly Methanol'!E42+'Yearly HC Ethylene'!E42+'Yearly HC Propylene'!E24 -> 0.33412854 | F15: ='Yearly Butadiene'!F28+'Yearly BTX'!F40+'Yearly Methanol'!F42+'Yearly HC Ethylene'!F42+'Yearly HC Propylene'!F24 -> 0.67855304 | G15: ='Yearly Butadiene'!G28+'Yearly BTX'!G40+'Yearly Methanol'!G42+'Yearly HC Ethylene'!G42+'Yearly HC Propylene'!G24 -> 1.0335186 | H15: ='Yearly Butadiene'!H28+'Yearly BTX'!H40+'Yearly Methanol'!H42+'Yearly HC Ethylene'!H42+'Yearly HC Propylene'!H24 -> 1.3992755 | I15: ='Yearly Butadiene'!I28+'Yearly BTX'!I40+'Yearly Methanol'!I42+'Yearly HC Ethylene'!I42+'Yearly HC Propylene'!I24 -> 1.7760795 | J15: ='Yearly Butadiene'!J28+'Yearly BTX'!J40+'Yearly Methanol'!J42+'Yearly HC Ethylene'!J42+'Yearly HC Propylene'!J24 -> 2.164192 | K15: ='Yearly Butadiene'!K28+'Yearly BTX'!K40+'Yearly Methanol'!K42+'Yearly HC Ethylene'!K42+'Yearly HC Propylene'!K24 -> 2.5638798 | ... AH15: ='Yearly Butadiene'!AH28+'Yearly BTX'!AH40+'Yearly Methanol'!AH42+'Yearly HC Ethylene'!AH42+'Yearly HC Propylene'!AH24 -> 15.817863 | AJ15: ='Yearly Butadiene'!AJ28+'Yearly BTX'!AJ40+'Yearly Methanol'!AJ42+'Yearly LC Ethylene'!D42+'Yearly LC Propylene'!D24 -> 0 | AK15: ='Yearly Butadiene'!AK28+'Yearly BTX'!AK40+'Yearly Methanol'!AK42+'Yearly LC Ethylene'!E42+'Yearly LC Propylene'!E24 -> 0.16706427 | AL15: ='Yearly Butadiene'!AL28+'Yearly BTX'!AL40+'Yearly Methanol'!AL42+'Yearly LC Ethylene'!F42+'Yearly LC Propylene'!F24 -> 0.33927652 | AM15: ='Yearly Butadiene'!AM28+'Yearly BTX'!AM40+'Yearly Methanol'!AM42+'Yearly LC Ethylene'!G42+'Yearly LC Propylene'!G24 -> 0.51675928 | AN15: ='Yearly Butadiene'!AN28+'Yearly BTX'!AN40+'Yearly Methanol'!AN42+'Yearly LC Ethylene'!H42+'Yearly LC Propylene'!H24 -> 0.69963773 | AO15: ='Yearly Butadiene'!AO28+'Yearly BTX'!AO40+'Yearly Methanol'!AO42+'Yearly LC Ethylene'!I42+'Yearly LC Propylene'!I24 -> 0.88803976 | AP15: ='Yearly Butadiene'!AP28+'Yearly BTX'!AP40+'Yearly Methanol'!AP42+'Yearly LC Ethylene'!J42+'Yearly LC Propylene'!J24 -> 1.082096 | AQ15: ='Yearly Butadiene'!AQ28+'Yearly BTX'!AQ40+'Yearly Methanol'!AQ42+'Yearly LC Ethylene'!K42+'Yearly LC Propylene'!K24 -> 1.2819399 | ... BN15: ='Yearly Butadiene'!BN28+'Yearly BTX'!BN40+'Yearly Methanol'!BN42+'Yearly LC Ethylene'!AH42+'Yearly LC Propylene'!AH24 -> 7.9089316 | BP15: 0 | BQ15: 0 | BR15: 0 | BS15: 0 | BT15: 0 | BU15: 0 | BV15: 0 | BW15: 0 | BX15: 0 | BY15: 0 | BZ15: 0 | CA15: 0 | CB15: 0 | CC15: 0 | CD15: 0 | CE15: 0 | CF15: 0 | CG15: 0 | CH15: 0 | CI15: 0 | CJ15: 0 | CK15: 0 | CL15: 0 | CM15: 0 | CN15: 0 | CO15: 0 | CP15: 0 | CQ15: 0 | CR15: 0 | CS15: 0 | CT15: 0 | CV15: 0 | CW15: 0 | CX15: 0 | CY15: 0 | CZ15: 0 | DA15: 0 | DB15: 0 | DC15: 0 | DD15: 0 | DE15: 0 | DF15: 0 | DG15: 0 | DH15: 0 | DI15: 0 | DJ15: 0 | DK15: 0 | DL15: 0 | DM15: 0 | DN15: 0 | DO15: 0 | DP15: 0 | DQ15: 0 | DR15: 0 | DS15: 0 | DT15: 0 | DU15: 0 | DV15: 0 | DW15: 0 | DX15: 0 | DY15: 0 | DZ15: 0 | EB15: Ferti | EE15: =EE6 -> 158.18581 | EF15: =BN5 -> 18 | EG15: =BN6 -> 0 | EH15: =0 -> 0 | EI15: 0 | EJ15: =EE15-SUM(EF15:EI15) -> 140.18581 | EK15: =EF15/$EE15 -> 0.11379023 | EL15: =EG15/$EE15 -> 0 | EM15: =EH15/$EE15 -> 0 | EN15: =EI15/$EE15 -> 0 | EO15: =EJ15/$EE15 -> 0.88620977 | EP15: =EF15/EF$22 -> 0.11817787 | EQ15: 0.11379023 | ER15: 0 | ES15: 0 | ET15: 0 | EU15: 0.88620977
A16: R | B16: Apparel - waste reduction | C16: mTons | D16: ='Yearly Butadiene'!D31+'Yearly BTX'!D46+'Yearly Methanol'!D48+'Yearly HC Ethylene'!D51+'Yearly HC Propylene'!D27 -> 0 | E16: ='Yearly Butadiene'!E31+'Yearly BTX'!E46+'Yearly Methanol'!E48+'Yearly HC Ethylene'!E51+'Yearly HC Propylene'!E27 -> 0.2946513 | F16: ='Yearly Butadiene'!F31+'Yearly BTX'!F46+'Yearly Methanol'!F48+'Yearly HC Ethylene'!F51+'Yearly HC Propylene'!F27 -> 0.59701519 | G16: ='Yearly Butadiene'!G31+'Yearly BTX'!G46+'Yearly Methanol'!G48+'Yearly HC Ethylene'!G51+'Yearly HC Propylene'!G27 -> 0.9072578 | H16: ='Yearly Butadiene'!H31+'Yearly BTX'!H46+'Yearly Methanol'!H48+'Yearly HC Ethylene'!H51+'Yearly HC Propylene'!H27 -> 1.2255488 | I16: ='Yearly Butadiene'!I31+'Yearly BTX'!I46+'Yearly Methanol'!I48+'Yearly HC Ethylene'!I51+'Yearly HC Propylene'!I27 -> 1.5520614 | J16: ='Yearly Butadiene'!J31+'Yearly BTX'!J46+'Yearly Methanol'!J48+'Yearly HC Ethylene'!J51+'Yearly HC Propylene'!J27 -> 1.8869727 | K16: ='Yearly Butadiene'!K31+'Yearly BTX'!K46+'Yearly Methanol'!K48+'Yearly HC Ethylene'!K51+'Yearly HC Propylene'!K27 -> 2.2304632 | ... AH16: ='Yearly Butadiene'!AH31+'Yearly BTX'!AH46+'Yearly Methanol'!AH48+'Yearly HC Ethylene'!AH51+'Yearly HC Propylene'!AH27 -> 6.1798822 | AJ16: ='Yearly Butadiene'!AJ31+'Yearly BTX'!AJ46+'Yearly Methanol'!AJ48+'Yearly LC Ethylene'!D51+'Yearly LC Propylene'!D27 -> 0 | AK16: ='Yearly Butadiene'!AK31+'Yearly BTX'!AK46+'Yearly Methanol'!AK48+'Yearly LC Ethylene'!E51+'Yearly LC Propylene'!E27 -> 0.14732565 | AL16: ='Yearly Butadiene'!AL31+'Yearly BTX'!AL46+'Yearly Methanol'!AL48+'Yearly LC Ethylene'!F51+'Yearly LC Propylene'!F27 -> 0.29850759 | AM16: ='Yearly Butadiene'!AM31+'Yearly BTX'!AM46+'Yearly Methanol'!AM48+'Yearly LC Ethylene'!G51+'Yearly LC Propylene'!G27 -> 0.4536289 | AN16: ='Yearly Butadiene'!AN31+'Yearly BTX'!AN46+'Yearly Methanol'!AN48+'Yearly LC Ethylene'!H51+'Yearly LC Propylene'!H27 -> 0.6127744 | AO16: ='Yearly Butadiene'!AO31+'Yearly BTX'!AO46+'Yearly Methanol'!AO48+'Yearly LC Ethylene'!I51+'Yearly LC Propylene'!I27 -> 0.77603072 | AP16: ='Yearly Butadiene'!AP31+'Yearly BTX'!AP46+'Yearly Methanol'!AP48+'Yearly LC Ethylene'!J51+'Yearly LC Propylene'!J27 -> 0.94348634 | AQ16: ='Yearly Butadiene'!AQ31+'Yearly BTX'!AQ46+'Yearly Methanol'!AQ48+'Yearly LC Ethylene'!K51+'Yearly LC Propylene'!K27 -> 1.1152316 | ... BN16: ='Yearly Butadiene'!BN31+'Yearly BTX'!BN46+'Yearly Methanol'!BN48+'Yearly LC Ethylene'!AH51+'Yearly LC Propylene'!AH27 -> 3.0899411 | BP16: 0 | BQ16: 0 | BR16: 0 | BS16: 0 | BT16: 0 | BU16: 0 | BV16: 0 | BW16: 0 | BX16: 0 | BY16: 0 | BZ16: 0 | CA16: 0 | CB16: 0 | CC16: 0 | CD16: 0 | CE16: 0 | CF16: 0 | CG16: 0 | CH16: 0 | CI16: 0 | CJ16: 0 | CK16: 0 | CL16: 0 | CM16: 0 | CN16: 0 | CO16: 0 | CP16: 0 | CQ16: 0 | CR16: 0 | CS16: 0 | CT16: 0 | CV16: 0 | CW16: 0 | CX16: 0 | CY16: 0 | CZ16: 0 | DA16: 0 | DB16: 0 | DC16: 0 | DD16: 0 | DE16: 0 | DF16: 0 | DG16: 0 | DH16: 0 | DI16: 0 | DJ16: 0 | DK16: 0 | DL16: 0 | DM16: 0 | DN16: 0 | DO16: 0 | DP16: 0 | DQ16: 0 | DR16: 0 | DS16: 0 | DT16: 0 | DU16: 0 | DV16: 0 | DW16: 0 | DX16: 0 | DY16: 0 | DZ16: 0 | EB16: Pack | EE16: =EE7 -> 277.98913 | EF16: =BN8 -> 19.249891 | EG16: =BN9 -> 51.505343 | EH16: =BN10+BN11 -> 37.977935 | EI16: =SUM('Yearly BTX'!BN76:BN77,'Yearly Butadiene'!BN49:BN50,'Yearly Methanol'!BN78:BN79,'Yearly LC Ethylene'!AH93:AH94,'Yearly HC Propylene'!AH44:AH45) -> 23.962811 | EJ16: =EE16-SUM(EF16:EI16) -> 145.29315 | EK16: =EF16/$EE16 -> 0.069246918 | EL16: =EG16/$EE16 -> 0.18527826 | EM16: =EH16/$EE16 -> 0.13661662 | EN16: =EI16/$EE16 -> 0.086200532 | EO16: =EJ16/$EE16 -> 0.52265767 | EP16: =EF16/EF$22 -> 0.12638394 | EQ16: 0.069246918 | ER16: 0.18527826 | ES16: 0.13661662 | ET16: 0.086200532 | EU16: 0.52265767
